Workbook

Sheet Questionário & Resultados
B2: Número | C2: Síntoma | D2: Si (x) | E2: No (x) | G2: Nutriente | H2: Síntomas Calculados | I2: Max Sintomas | J2: Racio % Calculado | K2: Necesidades | M2: Datos personales
B3: 1 | C3: Acné | G3: Vitamina A | H3: =INDEX('Tabela de Resultados'!$C$98:$AG$98,MATCH('Questionário & Resultados'!G3,'Tabela de Resultados'!$C$101:$AG$101,0)) -> 0 | I3: =INDEX('Tabela de Resultados'!$C$99:$AG$99,MATCH('Questionário & Resultados'!G3,'Tabela de Resultados'!$C$101:$AG$101,0)) -> 9 | J3: =INDEX('Tabela de Resultados'!$C$100:$AG$100,MATCH('Questionário & Resultados'!G3,'Tabela de Resultados'!$C$101:$AG$101,0)) -> 0 | K3: =IF(AND(J3>0,J3<0.3),"Em Falta",IF(J3>=0.3,"Urgente","OK")) -> OK | M3: Marcar con una cruz en caso de SI o NO
B4: 2 | C4: Aftas o cistitis | G4: Vitamina B1 | H4: =INDEX('Tabela de Resultados'!$C$98:$AG$98,MATCH('Questionário & Resultados'!G4,'Tabela de Resultados'!$C$101:$AG$101,0)) -> 0 | I4: =INDEX('Tabela de Resultados'!$C$99:$AG$99,MATCH('Questionário & Resultados'!G4,'Tabela de Resultados'!$C$101:$AG$101,0)) -> 18 | J4: =INDEX('Tabela de Resultados'!$C$100:$AG$100,MATCH('Questionário & Resultados'!G4,'Tabela de Resultados'!$C$101:$AG$101,0)) -> 0 | K4: =IF(AND(J4>0,J4<0.3),"Em Falta",IF(J4>=0.3,"Urgente","OK")) -> OK
B5: 3 | C5: Ansiedad o tensión | G5: Vitamina B2 | H5: =INDEX('Tabela de Resultados'!$C$98:$AG$98,MATCH('Questionário & Resultados'!G5,'Tabela de Resultados'!$C$101:$AG$101,0)) -> 0 | I5: =INDEX('Tabela de Resultados'!$C$99:$AG$99,MATCH('Questionário & Resultados'!G5,'Tabela de Resultados'!$C$101:$AG$101,0)) -> 9 | J5: =INDEX('Tabela de Resultados'!$C$100:$AG$100,MATCH('Questionário & Resultados'!G5,'Tabela de Resultados'!$C$101:$AG$101,0)) -> 0 | K5: =IF(AND(J5>0,J5<0.3),"Em Falta",IF(J5>=0.3,"Urgente","OK")) -> OK | M5: NOMBRE
B6: 4 | C6: Apatía | G6: Vitamina B3 | H6: =INDEX('Tabela de Resultados'!$C$98:$AG$98,MATCH('Questionário & Resultados'!G6,'Tabela de Resultados'!$C$101:$AG$101,0)) -> 0 | I6: =INDEX('Tabela de Resultados'!$C$99:$AG$99,MATCH('Questionário & Resultados'!G6,'Tabela de Resultados'!$C$101:$AG$101,0)) -> 10 | J6: =INDEX('Tabela de Resultados'!$C$100:$AG$100,MATCH('Questionário & Resultados'!G6,'Tabela de Resultados'!$C$101:$AG$101,0)) -> 0 | K6: =IF(AND(J6>0,J6<0.3),"Em Falta",IF(J6>=0.3,"Urgente","OK")) -> OK
B7: 5 | C7: Ardor en los pies o tobillos sensibles | G7: Vitamina B6 | H7: =INDEX('Tabela de Resultados'!$C$98:$AG$98,MATCH('Questionário & Resultados'!G7,'Tabela de Resultados'!$C$101:$AG$101,0)) -> 0 | I7: =INDEX('Tabela de Resultados'!$C$99:$AG$99,MATCH('Questionário & Resultados'!G7,'Tabela de Resultados'!$C$101:$AG$101,0)) -> 8 | J7: =INDEX('Tabela de Resultados'!$C$100:$AG$100,MATCH('Questionário & Resultados'!G7,'Tabela de Resultados'!$C$101:$AG$101,0)) -> 0 | K7: =IF(AND(J7>0,J7<0.3),"Em Falta",IF(J7>=0.3,"Urgente","OK")) -> OK
B8: 6 | C8: Latidos del corazón rápidos o irregulares | G8: Vitamina B12 | H8: =INDEX('Tabela de Resultados'!$C$98:$AG$98,MATCH('Questionário & Resultados'!G8,'Tabela de Resultados'!$C$101:$AG$101,0)) -> 0 | I8: =INDEX('Tabela de Resultados'!$C$99:$AG$99,MATCH('Questionário & Resultados'!G8,'Tabela de Resultados'!$C$101:$AG$101,0)) -> 9 | J8: =INDEX('Tabela de Resultados'!$C$100:$AG$100,MATCH('Questionário & Resultados'!G8,'Tabela de Resultados'!$C$101:$AG$101,0)) -> 0 | K8: =IF(AND(J8>0,J8<0.3),"Em Falta",IF(J8>=0.3,"Urgente","OK")) -> OK | M8: SEXO
B9: 7 | C9: Boca hipersensible al calor o al frío | G9: Vitamina C | H9: =INDEX('Tabela de Resultados'!$C$98:$AG$98,MATCH('Questionário & Resultados'!G9,'Tabela de Resultados'!$C$101:$AG$101,0)) -> 0 | I9: =INDEX('Tabela de Resultados'!$C$99:$AG$99,MATCH('Questionário & Resultados'!G9,'Tabela de Resultados'!$C$101:$AG$101,0)) -> 8 | J9: =INDEX('Tabela de Resultados'!$C$100:$AG$100,MATCH('Questionário & Resultados'!G9,'Tabela de Resultados'!$C$101:$AG$101,0)) -> 0 | K9: =IF(AND(J9>0,J9<0.3),"Em Falta",IF(J9>=0.3,"Urgente","OK")) -> OK
B10: 8 | C10: Cabello en mal estado | G10: Vitamina D | H10: =INDEX('Tabela de Resultados'!$C$98:$AG$98,MATCH('Questionário & Resultados'!G10,'Tabela de Resultados'!$C$101:$AG$101,0)) -> 0 | I10: =INDEX('Tabela de Resultados'!$C$99:$AG$99,MATCH('Questionário & Resultados'!G10,'Tabela de Resultados'!$C$101:$AG$101,0)) -> 9 | J10: =INDEX('Tabela de Resultados'!$C$100:$AG$100,MATCH('Questionário & Resultados'!G10,'Tabela de Resultados'!$C$101:$AG$101,0)) -> 0 | K10: =IF(AND(J10>0,J10<0.3),"Em Falta",IF(J10>=0.3,"Urgente","OK")) -> OK
B11: 9 | C11: Cabello seco | G11: Vitamina E | H11: =INDEX('Tabela de Resultados'!$C$98:$AG$98,MATCH('Questionário & Resultados'!G11,'Tabela de Resultados'!$C$101:$AG$101,0)) -> 0 | I11: =INDEX('Tabela de Resultados'!$C$99:$AG$99,MATCH('Questionário & Resultados'!G11,'Tabela de Resultados'!$C$101:$AG$101,0)) -> 8 | J11: =INDEX('Tabela de Resultados'!$C$100:$AG$100,MATCH('Questionário & Resultados'!G11,'Tabela de Resultados'!$C$101:$AG$101,0)) -> 0 | K11: =IF(AND(J11>0,J11<0.3),"Em Falta",IF(J11>=0.3,"Urgente","OK")) -> OK | M11: EDAD
B12: 10 | C12: Cabello opaco o graso | G12: Ácido Fólico | H12: =INDEX('Tabela de Resultados'!$C$98:$AG$98,MATCH('Questionário & Resultados'!G12,'Tabela de Resultados'!$C$101:$AG$101,0)) -> 0 | I12: =INDEX('Tabela de Resultados'!$C$99:$AG$99,MATCH('Questionário & Resultados'!G12,'Tabela de Resultados'!$C$101:$AG$101,0)) -> 9 | J12: =INDEX('Tabela de Resultados'!$C$100:$AG$100,MATCH('Questionário & Resultados'!G12,'Tabela de Resultados'!$C$101:$AG$101,0)) -> 0 | K12: =IF(AND(J12>0,J12<0.3),"Em Falta",IF(J12>=0.3,"Urgente","OK")) -> OK
B13: 11 | C13: Calambres o temblores | G13: Biotina | H13: =INDEX('Tabela de Resultados'!$C$98:$AG$98,MATCH('Questionário & Resultados'!G13,'Tabela de Resultados'!$C$101:$AG$101,0)) -> 0 | I13: =INDEX('Tabela de Resultados'!$C$99:$AG$99,MATCH('Questionário & Resultados'!G13,'Tabela de Resultados'!$C$101:$AG$101,0)) -> 9 | J13: =INDEX('Tabela de Resultados'!$C$100:$AG$100,MATCH('Questionário & Resultados'!G13,'Tabela de Resultados'!$C$101:$AG$101,0)) -> 0 | K13: =IF(AND(J13>0,J13<0.3),"Em Falta",IF(J13>=0.3,"Urgente","OK")) -> OK
B14: 12 | C14: Cansancio después de un ejercicio ligero | G14: Cálcio | H14: =INDEX('Tabela de Resultados'!$C$98:$AG$98,MATCH('Questionário & Resultados'!G14,'Tabela de Resultados'!$C$101:$AG$101,0)) -> 0 | I14: =INDEX('Tabela de Resultados'!$C$99:$AG$99,MATCH('Questionário & Resultados'!G14,'Tabela de Resultados'!$C$101:$AG$101,0)) -> 9 | J14: =INDEX('Tabela de Resultados'!$C$100:$AG$100,MATCH('Questionário & Resultados'!G14,'Tabela de Resultados'!$C$101:$AG$101,0)) -> 0 | K14: =IF(AND(J14>0,J14<0.3),"Em Falta",IF(J14>=0.3,"Urgente","OK")) -> OK | M14: PATOLOGÍAS | OTROS SÍNTOMAS ESPECÍFICOS
B15: 13 | C15: Caries | G15: Crómio | H15: =INDEX('Tabela de Resultados'!$C$98:$AG$98,MATCH('Questionário & Resultados'!G15,'Tabela de Resultados'!$C$101:$AG$101,0)) -> 0 | I15: =INDEX('Tabela de Resultados'!$C$99:$AG$99,MATCH('Questionário & Resultados'!G15,'Tabela de Resultados'!$C$101:$AG$101,0)) -> 6 | J15: =INDEX('Tabela de Resultados'!$C$100:$AG$100,MATCH('Questionário & Resultados'!G15,'Tabela de Resultados'!$C$101:$AG$101,0)) -> 0 | K15: =IF(AND(J15>0,J15<0.3),"Em Falta",IF(J15>=0.3,"Urgente","OK")) -> OK
B16: 14 | C16: Caspa | G16: Ferro | H16: =INDEX('Tabela de Resultados'!$C$98:$AG$98,MATCH('Questionário & Resultados'!G16,'Tabela de Resultados'!$C$101:$AG$101,0)) -> 0 | I16: =INDEX('Tabela de Resultados'!$C$99:$AG$99,MATCH('Questionário & Resultados'!G16,'Tabela de Resultados'!$C$101:$AG$101,0)) -> 6 | J16: =INDEX('Tabela de Resultados'!$C$100:$AG$100,MATCH('Questionário & Resultados'!G16,'Tabela de Resultados'!$C$101:$AG$101,0)) -> 0 | K16: =IF(AND(J16>0,J16<0.3),"Em Falta",IF(J16>=0.3,"Urgente","OK")) -> OK
B17: 15 | C17: Cataratas | G17: Magnésio | H17: =INDEX('Tabela de Resultados'!$C$98:$AG$98,MATCH('Questionário & Resultados'!G17,'Tabela de Resultados'!$C$101:$AG$101,0)) -> 0 | I17: =INDEX('Tabela de Resultados'!$C$99:$AG$99,MATCH('Questionário & Resultados'!G17,'Tabela de Resultados'!$C$101:$AG$101,0)) -> 14 | J17: =INDEX('Tabela de Resultados'!$C$100:$AG$100,MATCH('Questionário & Resultados'!G17,'Tabela de Resultados'!$C$101:$AG$101,0)) -> 0 | K17: =IF(AND(J17>0,J17<0.3),"Em Falta",IF(J17>=0.3,"Urgente","OK")) -> OK
B18: 16 | C18: Cicatrización lenta | G18: Manganésio | H18: =INDEX('Tabela de Resultados'!$C$98:$AG$98,MATCH('Questionário & Resultados'!G18,'Tabela de Resultados'!$C$101:$AG$101,0)) -> 0 | I18: =INDEX('Tabela de Resultados'!$C$99:$AG$99,MATCH('Questionário & Resultados'!G18,'Tabela de Resultados'!$C$101:$AG$101,0)) -> 5 | J18: =INDEX('Tabela de Resultados'!$C$100:$AG$100,MATCH('Questionário & Resultados'!G18,'Tabela de Resultados'!$C$101:$AG$101,0)) -> 0 | K18: =IF(AND(J18>0,J18<0.3),"Em Falta",IF(J18>=0.3,"Urgente","OK")) -> OK
B19: 17 | C19: Resfriados frecuentes | G19: Selénio | H19: =INDEX('Tabela de Resultados'!$C$98:$AG$98,MATCH('Questionário & Resultados'!G19,'Tabela de Resultados'!$C$101:$AG$101,0)) -> 0 | I19: =INDEX('Tabela de Resultados'!$C$99:$AG$99,MATCH('Questionário & Resultados'!G19,'Tabela de Resultados'!$C$101:$AG$101,0)) -> 4 | J19: =INDEX('Tabela de Resultados'!$C$100:$AG$100,MATCH('Questionário & Resultados'!G19,'Tabela de Resultados'!$C$101:$AG$101,0)) -> 0 | K19: =IF(AND(J19>0,J19<0.3),"Em Falta",IF(J19>=0.3,"Urgente","OK")) -> OK
B20: 18 | C20: Contracciones musculares | G20: Zinco | H20: =INDEX('Tabela de Resultados'!$C$98:$AG$98,MATCH('Questionário & Resultados'!G20,'Tabela de Resultados'!$C$101:$AG$101,0)) -> 0 | I20: =INDEX('Tabela de Resultados'!$C$99:$AG$99,MATCH('Questionário & Resultados'!G20,'Tabela de Resultados'!$C$101:$AG$101,0)) -> 8 | J20: =INDEX('Tabela de Resultados'!$C$100:$AG$100,MATCH('Questionário & Resultados'!G20,'Tabela de Resultados'!$C$101:$AG$101,0)) -> 0 | K20: =IF(AND(J20>0,J20<0.3),"Em Falta",IF(J20>=0.3,"Urgente","OK")) -> OK
B21: 19 | C21: Crisis o convulsiones | G21: Ómegas 3 e 6 | H21: =INDEX('Tabela de Resultados'!$C$98:$AG$98,MATCH('Questionário & Resultados'!G21,'Tabela de Resultados'!$C$101:$AG$101,0)) -> 0 | I21: =INDEX('Tabela de Resultados'!$C$99:$AG$99,MATCH('Questionário & Resultados'!G21,'Tabela de Resultados'!$C$101:$AG$101,0)) -> 13 | J21: =INDEX('Tabela de Resultados'!$C$100:$AG$100,MATCH('Questionário & Resultados'!G21,'Tabela de Resultados'!$C$101:$AG$101,0)) -> 0 | K21: =IF(AND(J21>0,J21<0.3),"Em Falta",IF(J21>=0.3,"Urgente","OK")) -> OK
B22: 20 | C22: Depresión
B23: 21 | C23: Dermatitis | G23: Suplemento Específico | H23: Sintomas Calculados | I23: Max Sintomas | J23: Racio % Calculado | K23: Necessidade
B24: 22 | C24: Diarrea | G24: Alho | H24: =INDEX('Tabela de Resultados'!$C$98:$AG$98,MATCH('Questionário & Resultados'!G24,'Tabela de Resultados'!$C$101:$AG$101,0)) -> 0 | I24: =INDEX('Tabela de Resultados'!$C$99:$AG$99,MATCH('Questionário & Resultados'!G24,'Tabela de Resultados'!$C$101:$AG$101,0)) -> 9 | J24: =INDEX('Tabela de Resultados'!$C$100:$AG$100,MATCH('Questionário & Resultados'!G24,'Tabela de Resultados'!$C$101:$AG$101,0)) -> 0 | K24: =IF(AND(J24>0,J24<0.3),"Em Falta",IF(J24>=0.3,"Urgente","OK")) -> OK
B25: 23 | C25: Dificultad para recordar los sueños | G25: Black Cohosh | H25: =INDEX('Tabela de Resultados'!$C$98:$AG$98,MATCH('Questionário & Resultados'!G25,'Tabela de Resultados'!$C$101:$AG$101,0)) -> 0 | I25: =INDEX('Tabela de Resultados'!$C$99:$AG$99,MATCH('Questionário & Resultados'!G25,'Tabela de Resultados'!$C$101:$AG$101,0)) -> 1 | J25: =INDEX('Tabela de Resultados'!$C$100:$AG$100,MATCH('Questionário & Resultados'!G25,'Tabela de Resultados'!$C$101:$AG$101,0)) -> 0 | K25: =IF(AND(J25>0,J25<0.3),"Em Falta",IF(J25>=0.3,"Urgente","OK")) -> OK | M25: MEDICACACIÓN ACTUAL
B26: 24 | C26: Dificultad para concentrarse | G26: Coenzima Q10 | H26: =INDEX('Tabela de Resultados'!$C$98:$AG$98,MATCH('Questionário & Resultados'!G26,'Tabela de Resultados'!$C$101:$AG$101,0)) -> 0 | I26: =INDEX('Tabela de Resultados'!$C$99:$AG$99,MATCH('Questionário & Resultados'!G26,'Tabela de Resultados'!$C$101:$AG$101,0)) -> 3 | J26: =INDEX('Tabela de Resultados'!$C$100:$AG$100,MATCH('Questionário & Resultados'!G26,'Tabela de Resultados'!$C$101:$AG$101,0)) -> 0 | K26: =IF(AND(J26>0,J26<0.3),"Em Falta",IF(J26>=0.3,"Urgente","OK")) -> OK | M26: NOMBRE MEDICAMENTO | N26: FUNCIÓN DEL MEDICAMENTO
B27: 25 | C27: Olfato o gusto disminuido | G27: Concentrado de Frutas e Vegetais | H27: =INDEX('Tabela de Resultados'!$C$98:$AG$98,MATCH('Questionário & Resultados'!G27,'Tabela de Resultados'!$C$101:$AG$101,0)) -> 0 | I27: =INDEX('Tabela de Resultados'!$C$99:$AG$99,MATCH('Questionário & Resultados'!G27,'Tabela de Resultados'!$C$101:$AG$101,0)) -> 4 | J27: =INDEX('Tabela de Resultados'!$C$100:$AG$100,MATCH('Questionário & Resultados'!G27,'Tabela de Resultados'!$C$101:$AG$101,0)) -> 0 | K27: =IF(AND(J27>0,J27<0.3),"Em Falta",IF(J27>=0.3,"Urgente","OK")) -> OK
B28: 26 | C28: Dolores de cabeza o migrañas | G28: Fibra em Pó | H28: =INDEX('Tabela de Resultados'!$C$98:$AG$98,MATCH('Questionário & Resultados'!G28,'Tabela de Resultados'!$C$101:$AG$101,0)) -> 0 | I28: =INDEX('Tabela de Resultados'!$C$99:$AG$99,MATCH('Questionário & Resultados'!G28,'Tabela de Resultados'!$C$101:$AG$101,0)) -> 1 | J28: =INDEX('Tabela de Resultados'!$C$100:$AG$100,MATCH('Questionário & Resultados'!G28,'Tabela de Resultados'!$C$101:$AG$101,0)) -> 0 | K28: =IF(AND(J28>0,J28<0.3),"Em Falta",IF(J28>=0.3,"Urgente","OK")) -> OK
B29: 27 | C29: Dolores de crecimiento durante la infancia | G29: Fibra Mastigável | H29: =INDEX('Tabela de Resultados'!$C$98:$AG$98,MATCH('Questionário & Resultados'!G29,'Tabela de Resultados'!$C$101:$AG$101,0)) -> 0 | I29: =INDEX('Tabela de Resultados'!$C$99:$AG$99,MATCH('Questionário & Resultados'!G29,'Tabela de Resultados'!$C$101:$AG$101,0)) -> 2 | J29: =INDEX('Tabela de Resultados'!$C$100:$AG$100,MATCH('Questionário & Resultados'!G29,'Tabela de Resultados'!$C$101:$AG$101,0)) -> 0 | K29: =IF(AND(J29>0,J29<0.3),"Em Falta",IF(J29>=0.3,"Urgente","OK")) -> OK
B30: 28 | C30: Dolores de estómago | G30: Ginseng Siberiano Plus | H30: =INDEX('Tabela de Resultados'!$C$98:$AG$98,MATCH('Questionário & Resultados'!G30,'Tabela de Resultados'!$C$101:$AG$101,0)) -> 0 | I30: =INDEX('Tabela de Resultados'!$C$99:$AG$99,MATCH('Questionário & Resultados'!G30,'Tabela de Resultados'!$C$101:$AG$101,0)) -> 5 | J30: =INDEX('Tabela de Resultados'!$C$100:$AG$100,MATCH('Questionário & Resultados'!G30,'Tabela de Resultados'!$C$101:$AG$101,0)) -> 0 | K30: =IF(AND(J30>0,J30<0.3),"Em Falta",IF(J30>=0.3,"Urgente","OK")) -> OK
B31: 29 | C31: Dolor de espalda | G31: Glucosamina com Boswellia | H31: =INDEX('Tabela de Resultados'!$C$98:$AG$98,MATCH('Questionário & Resultados'!G31,'Tabela de Resultados'!$C$101:$AG$101,0)) -> 0 | I31: =INDEX('Tabela de Resultados'!$C$99:$AG$99,MATCH('Questionário & Resultados'!G31,'Tabela de Resultados'!$C$101:$AG$101,0)) -> 3 | J31: =INDEX('Tabela de Resultados'!$C$100:$AG$100,MATCH('Questionário & Resultados'!G31,'Tabela de Resultados'!$C$101:$AG$101,0)) -> 0 | K31: =IF(AND(J31>0,J31<0.3),"Em Falta",IF(J31>=0.3,"Urgente","OK")) -> OK
B32: 30 | C32: Dolor en las articulaciones, enfermedades inflamatorias (por ejemplo artritis) o rigidez | G32: Mirtilo com Luteína | H32: =INDEX('Tabela de Resultados'!$C$98:$AG$98,MATCH('Questionário & Resultados'!G32,'Tabela de Resultados'!$C$101:$AG$101,0)) -> 0 | I32: =INDEX('Tabela de Resultados'!$C$99:$AG$99,MATCH('Questionário & Resultados'!G32,'Tabela de Resultados'!$C$101:$AG$101,0)) -> 3 | J32: =INDEX('Tabela de Resultados'!$C$100:$AG$100,MATCH('Questionário & Resultados'!G32,'Tabela de Resultados'!$C$101:$AG$101,0)) -> 0 | K32: =IF(AND(J32>0,J32<0.3),"Em Falta",IF(J32>=0.3,"Urgente","OK")) -> OK
B33: 31 | C33: Dolores en los ojos | G33: Primrose Plus | H33: =INDEX('Tabela de Resultados'!$C$98:$AG$98,MATCH('Questionário & Resultados'!G33,'Tabela de Resultados'!$C$101:$AG$101,0)) -> 0 | I33: =INDEX('Tabela de Resultados'!$C$99:$AG$99,MATCH('Questionário & Resultados'!G33,'Tabela de Resultados'!$C$101:$AG$101,0)) -> 2 | J33: =INDEX('Tabela de Resultados'!$C$100:$AG$100,MATCH('Questionário & Resultados'!G33,'Tabela de Resultados'!$C$101:$AG$101,0)) -> 0 | K33: =IF(AND(J33>0,J33<0.3),"Em Falta",IF(J33>=0.3,"Urgente","OK")) -> OK
B34: 32 | C34: Eczema | G34: Proteína 100% Vegetal | H34: =INDEX('Tabela de Resultados'!$C$98:$AG$98,MATCH('Questionário & Resultados'!G34,'Tabela de Resultados'!$C$101:$AG$101,0)) -> 0 | I34: =INDEX('Tabela de Resultados'!$C$99:$AG$99,MATCH('Questionário & Resultados'!G34,'Tabela de Resultados'!$C$101:$AG$101,0)) -> 7 | J34: =INDEX('Tabela de Resultados'!$C$100:$AG$100,MATCH('Questionário & Resultados'!G34,'Tabela de Resultados'!$C$101:$AG$101,0)) -> 0 | K34: =IF(AND(J34>0,J34<0.3),"Em Falta",IF(J34>=0.3,"Urgente","OK")) -> OK
B35: 33 | C35: Pelo canoso prematuro | G35: Saw Palmetto e raiz de urtiga | H35: =INDEX('Tabela de Resultados'!$C$98:$AG$98,MATCH('Questionário & Resultados'!G35,'Tabela de Resultados'!$C$101:$AG$101,0)) -> 0 | I35: =INDEX('Tabela de Resultados'!$C$99:$AG$99,MATCH('Questionário & Resultados'!G35,'Tabela de Resultados'!$C$101:$AG$101,0)) -> 3 | J35: =INDEX('Tabela de Resultados'!$C$100:$AG$100,MATCH('Questionário & Resultados'!G35,'Tabela de Resultados'!$C$101:$AG$101,0)) -> 0 | K35: =IF(AND(J35>0,J35<0.3),"Em Falta",IF(J35>=0.3,"Urgente","OK")) -> OK
B36: 34 | C36: Manchas faciales (oscuras) | M36: RECOMENDACION NUTRILITE
B37: 35 | C37: Espasmos musculares | M37: NOMBRE NUTRILITE | N37: FUNCION SUPLEMENTO
B38: 36 | C38: Estrías
B39: 37 | C39: Fatiga / somnolencia
B40: 38 | C40: Falta de deseo sexual
B41: 39 | C41: Falta de apetito
...

Sheet Bibliografia
B2: Os resultados têm base cientificamente fundamentada por Patrick Holford (especialista mundial em Nutrição & Assessor de Nutrição e Saúde) – “Biblia da Alimentação”. O ficheiro foi elaborado pelo especialista em Nutrição e na Nutrilite Pedro Pereira em conjunto com Dra Filipa Vicente (Nutricionista Doutoranda na Faculdade de Barcelona em Nutrição Desportiva), Luis Collantes (especialista em Nutrição e um dos maiores especialistas mundiais da Nutrilite) e Dr Dario Sanchez (médico Nutrilite do Nutrilite Health Institute).

Sheet Tabela de Resultados
B2: Sintoma | C2: Vitamina A | D2: Vitamina B1 | E2: Vitamina B2 | F2: Vitamina B3 | G2: Vitamina B6 | H2: Vitamina B12 | I2: Vitamina C | J2: Vitamina D | K2: Vitamina E | L2: Ácido Fólico | M2: Biotina | N2: Cálcio | O2: Crómio | P2: Ferro | Q2: Magnésio | R2: Manganésio | S2: Selénio | T2: Zinco | U2: Ómegas 3 e 6 | V2: Alho | W2: Black Cohosh | X2: Coenzima Q10 | Y2: Concentrado de Frutas e Vegetais | Z2: Fibra em Pó | AA2: Fibra Mastigável | AB2: Ginseng Siberiano Plus | AC2: Glucosamina com Boswellia | AD2: Mirtilo com Luteína | AE2: Primrose Plus | AF2: Proteína 100% Vegetal | AG2: Saw Palmetto e raiz de urtiga | AI2: Input
B3: 1 | C3: =IF($AI$3="","",1) | F3: =IF($AI$3="","",1) | T3: =IF($AI$3="","",1) | V3: =IF($AI$3="","",1) | AI3: =IF('Questionário & Resultados'!D3="x",1,"")
B4: 2 | C4: =IF($AI$4="","",1) | AI4: =IF('Questionário & Resultados'!D4="x",1,"")
B5: 3 | D5: =IF($AI$5="","",1) | F5: =IF($AI$5="","",1) | H5: =IF($AI$5="","",1) | J5: =IF($AI$5="","",1) | L5: =IF($AI$5="","",1) | N5: =IF($AI$5="","",1) | Q5: =IF($AI$5="","",1) | AI5: =IF('Questionário & Resultados'!D5="x",1,"")
B6: 4 | D6: =IF($AI$6="","",1) | AI6: =IF('Questionário & Resultados'!D6="x",1,"")
B7: 5 | D7: =IF($AI$7="","",1) | AI7: =IF('Questionário & Resultados'!D7="x",1,"")
B8: 6 | D8: =IF($AI$8="","",1) | Q8: =IF($AI$8="","",1) | AI8: =IF('Questionário & Resultados'!D8="x",1,"")
B9: 7 | H9: =IF($AI$9="","",1) | AI9: =IF('Questionário & Resultados'!D9="x",1,"")
B10: 8 | M10: =IF($AI$10="","",1) | AI10: =IF('Questionário & Resultados'!D10="x",1,"")
B11: 9 | U11: =IF($AI$11="","",1) | AI11: =IF('Questionário & Resultados'!D11="x",1,"")
B12: 10 | E12: =IF($AI$12="","",1) | AI12: =IF('Questionário & Resultados'!D12="x",1,"")
B13: 11 | D13: =IF($AI$13="","",1) | G13: =IF($AI$13="","",1) | N13: =IF($AI$13="","",1) | Q13: =IF($AI$13="","",1) | AI13: =IF('Questionário & Resultados'!D13="x",1,"")
B14: 12 | D14: =IF($AI$14="","",1) | K14: =IF($AI$14="","",1) | X14: =IF($AI$14="","",1) | AB14: =IF($AI$14="","",1) | AF14: =IF($AI$14="","",1) | AI14: =IF('Questionário & Resultados'!D14="x",1,"")
B15: 13 | N15: =IF($AI$15="","",1) | AI15: =IF('Questionário & Resultados'!D15="x",1,"")
B16: 14 | C16: =IF($AI$16="","",1) | AI16: =IF('Questionário & Resultados'!D16="x",1,"")
B17: 15 | E17: =IF($AI$17="","",1) | S17: =IF($AI$17="","",1) | AI17: =IF('Questionário & Resultados'!D17="x",1,"")
B18: 16 | I18: =IF($AI$18="","",1) | K18: =IF($AI$18="","",1) | T18: =IF($AI$18="","",1) | AI18: =IF('Questionário & Resultados'!D18="x",1,"")
B19: 17 | C19: =IF($AI$19="","",1) | I19: =IF($AI$19="","",1) | T19: =IF($AI$19="","",1) | V19: =IF($AI$19="","",1) | Y19: =IF($AI$19="","",1) | AI19: =IF('Questionário & Resultados'!D19="x",1,"")
B20: 18 | Q20: =IF($AI$20="","",1) | R20: =IF($AI$20="","",1) | AF20: =IF($AI$20="","",1) | AI20: =IF('Questionário & Resultados'!D20="x",1,"")
B21: 19 | Q21: =IF($AI$21="","",1) | R21: =IF($AI$21="","",1) | AI21: =IF('Questionário & Resultados'!D21="x",1,"")
B22: 20 | F22: =IF($AI$22="","",1) | G22: =IF($AI$22="","",1) | L22: =IF($AI$22="","",1) | Q22: =IF($AI$22="","",1) | AI22: =IF('Questionário & Resultados'!D22="x",1,"")
B23: 21 | E23: =IF($AI$23="","",1) | H23: =IF($AI$23="","",1) | M23: =IF($AI$23="","",1) | AI23: =IF('Questionário & Resultados'!D23="x",1,"")
B24: 22 | C24: =IF($AI$24="","",1) | F24: =IF($AI$24="","",1) | AI24: =IF('Questionário & Resultados'!D24="x",1,"")
B25: 23 | G25: =IF($AI$25="","",1) | AI25: =IF('Questionário & Resultados'!D25="x",1,"")
B26: 24 | D26: =IF($AI$26="","",1) | U26: =IF($AI$26="","",1) | AI26: =IF('Questionário & Resultados'!D26="x",1,"")
B27: 25 | T27: =IF($AI$27="","",1) | AI27: =IF('Questionário & Resultados'!D27="x",1,"")
B28: 26 | F28: =IF($AI$28="","",1) | J28: =IF($AI$28="","",1) | N28: =IF($AI$28="","",1) | Q28: =IF($AI$28="","",1) | AI28: =IF('Questionário & Resultados'!D28="x",1,"")
B29: 27 | R29: =IF($AI$29="","",1) | AI29: =IF('Questionário & Resultados'!D29="x",1,"")
B30: 28 | D30: =IF($AI$30="","",1) | L30: =IF($AI$30="","",1) | Y30: =IF($AI$30="","",1) | AA30: =IF($AI$30="","",1) | AI30: =IF('Questionário & Resultados'!D30="x",1,"")
B31: 29 | J31: =IF($AI$31="","",1) | V31: =IF($AI$31="","",1) | AC31: =IF($AI$31="","",1) | AI31: =IF('Questionário & Resultados'!D31="x",1,"")
B32: 30 | J32: =IF($AI$32="","",1) | N32: =IF($AI$32="","",1) | U32: =IF($AI$32="","",1) | V32: =IF($AI$32="","",1) | AC32: =IF($AI$32="","",1) | AI32: =IF('Questionário & Resultados'!D32="x",1,"")
B33: 31 | D33: =IF($AI$33="","",1) | AD33: =IF($AI$33="","",1) | AI33: =IF('Questionário & Resultados'!D33="x",1,"")
B34: 32 | E34: =IF($AI$34="","",1) | H34: =IF($AI$34="","",1) | L34: =IF($AI$34="","",1) | U34: =IF($AI$34="","",1) | AI34: =IF('Questionário & Resultados'!D34="x",1,"")
B35: 33 | L35: =IF($AI$35="","",1) | M35: =IF($AI$35="","",1) | O35: =IF($AI$35="","",1) | AI35: =IF('Questionário & Resultados'!D35="x",1,"")
B36: 34 | I36: =IF($AI$36="","",1) | K36: =IF($AI$36="","",1) | AI36: =IF('Questionário & Resultados'!D36="x",1,"")
B37: 35 | J37: =IF($AI$37="","",1) | AF37: =IF($AI$37="","",1) | AI37: =IF('Questionário & Resultados'!D37="x",1,"")
B38: 36 | T38: =IF($AI$38="","",1) | AI38: =IF('Questionário & Resultados'!D38="x",1,"")
B39: 37 | P39: =IF($AI$39="","",1) | X39: =IF($AI$39="","",1) | AB39: =IF($AI$39="","",1) | AI39: =IF('Questionário & Resultados'!D39="x",1,"")
B40: 38 | K40: =IF($AI$40="","",1) | AI40: =IF('Questionário & Resultados'!D40="x",1,"")
B41: 39 | L41: =IF($AI$41="","",1) | M41: =IF($AI$41="","",1) | P41: =IF($AI$41="","",1) | AI41: =IF('Questionário & Resultados'!D41="x",1,"")
...

Sheet Base de Dados
B2: Micronutriente | C2: Sintomas (Duplicação) | E2: Número | F2: Sintomas | G2: Micronutriente | I2: Micronutriente | J2: Micronutriente (NEW) | K2: Número de Sintomas | L2: Crosscheck T. de Resultados | M2: Diferença | O2: Sintomas | P2: Número
B3: Alho | C3: Acne | E3: =INDEX($P$3:$P$97,MATCH(F3,$O$3:$O$97,0)) -> 1 | F3: Acne | G3: Alho | I3: Vitamina A | J3: Vitamina A | K3: =INDEX('Tabela de Resultados'!$C$99:$AG$99,MATCH('Base de Dados'!J3,'Tabela de Resultados'!$C$2:$AG$2,0)) -> 9 | L3: =INDEX('Perfil Vitaminico'!$C$3:$C$13,MATCH('Base de Dados'!I3,'Perfil Vitaminico'!$B$3:$B$13,0)) -> 9 | M3: =K3=L3 -> TRUE | O3: Acne | P3: 1
B4: Vitamina A | C4: Acne | E4: =INDEX($P$3:$P$97,MATCH(F4,$O$3:$O$97,0)) -> 1 | F4: Acne | G4: Vitamina A | I4: Vitamina B1 (Tiamina) | J4: Vitamina B1 | K4: =INDEX('Tabela de Resultados'!$C$99:$AG$99,MATCH('Base de Dados'!J4,'Tabela de Resultados'!$C$2:$AG$2,0)) -> 18 | L4: =INDEX('Perfil Vitaminico'!$C$3:$C$13,MATCH('Base de Dados'!I4,'Perfil Vitaminico'!$B$3:$B$13,0)) -> 18 | M4: =K4=L4 -> TRUE | O4: Aftas ou cistite | P4: 2
B5: Vitamina B3 (Niacina) | C5: Acne | E5: =INDEX($P$3:$P$97,MATCH(F5,$O$3:$O$97,0)) -> 1 | F5: Acne | G5: Vitamina B3 (Niacina) | I5: Vitamina B2 (Riboflavina) | J5: Vitamina B2 | K5: =INDEX('Tabela de Resultados'!$C$99:$AG$99,MATCH('Base de Dados'!J5,'Tabela de Resultados'!$C$2:$AG$2,0)) -> 9 | L5: =INDEX('Perfil Vitaminico'!$C$3:$C$13,MATCH('Base de Dados'!I5,'Perfil Vitaminico'!$B$3:$B$13,0)) -> 9 | M5: =K5=L5 -> TRUE | O5: Ansiedade ou tensão | P5: 3
B6: Zinco | C6: Acne | E6: =INDEX($P$3:$P$97,MATCH(F6,$O$3:$O$97,0)) -> 1 | F6: Acne | G6: Zinco | I6: Vitamina B3 (Niacina) | J6: Vitamina B3 | K6: =INDEX('Tabela de Resultados'!$C$99:$AG$99,MATCH('Base de Dados'!J6,'Tabela de Resultados'!$C$2:$AG$2,0)) -> 10 | L6: =INDEX('Perfil Vitaminico'!$C$3:$C$13,MATCH('Base de Dados'!I6,'Perfil Vitaminico'!$B$3:$B$13,0)) -> 10 | M6: =K6=L6 -> TRUE | O6: Apatia | P6: 4
B7: Vitamina A | C7: Aftas ou cistite | E7: =INDEX($P$3:$P$97,MATCH(F7,$O$3:$O$97,0)) -> 2 | F7: Aftas ou cistite | G7: Vitamina A | I7: Vitamina B6 (Piridoxina) | J7: Vitamina B6 | K7: =INDEX('Tabela de Resultados'!$C$99:$AG$99,MATCH('Base de Dados'!J7,'Tabela de Resultados'!$C$2:$AG$2,0)) -> 8 | L7: =INDEX('Perfil Vitaminico'!$C$3:$C$13,MATCH('Base de Dados'!I7,'Perfil Vitaminico'!$B$3:$B$13,0)) -> 8 | M7: =K7=L7 -> TRUE | O7: Ardor nos pés ou tornozelos sensíveis | P7: 5
B8: Ácido Fólico (Vitamina B9) | C8: Ansiedade ou tensão | E8: =INDEX($P$3:$P$97,MATCH(F8,$O$3:$O$97,0)) -> 3 | F8: Ansiedade ou tensão | G8: Ácido Fólico (Vitamina B9) | I8: Vitamina B12 (Cobalamina) | J8: Vitamina B12 | K8: =INDEX('Tabela de Resultados'!$C$99:$AG$99,MATCH('Base de Dados'!J8,'Tabela de Resultados'!$C$2:$AG$2,0)) -> 9 | L8: =INDEX('Perfil Vitaminico'!$C$3:$C$13,MATCH('Base de Dados'!I8,'Perfil Vitaminico'!$B$3:$B$13,0)) -> 9 | M8: =K8=L8 -> TRUE | O8: Batimentos cardíacos irregulares ou rápidos | P8: 6
B9: Cálcio | C9: Ansiedade ou tensão | E9: =INDEX($P$3:$P$97,MATCH(F9,$O$3:$O$97,0)) -> 3 | F9: Ansiedade ou tensão | G9: Cálcio | I9: Vitamina C (Ácido Ascórbico) | J9: Vitamina C | K9: =INDEX('Tabela de Resultados'!$C$99:$AG$99,MATCH('Base de Dados'!J9,'Tabela de Resultados'!$C$2:$AG$2,0)) -> 8 | L9: =INDEX('Perfil Vitaminico'!$C$3:$C$13,MATCH('Base de Dados'!I9,'Perfil Vitaminico'!$B$3:$B$13,0)) -> 8 | M9: =K9=L9 -> TRUE | O9: Boca hipersensível ao calor ou frio | P9: 7
B10: Magnésio | C10: Ansiedade ou tensão | E10: =INDEX($P$3:$P$97,MATCH(F10,$O$3:$O$97,0)) -> 3 | F10: Ansiedade ou tensão | G10: Magnésio | I10: Vitamina D | J10: Vitamina D | K10: =INDEX('Tabela de Resultados'!$C$99:$AG$99,MATCH('Base de Dados'!J10,'Tabela de Resultados'!$C$2:$AG$2,0)) -> 9 | L10: =INDEX('Perfil Vitaminico'!$C$3:$C$13,MATCH('Base de Dados'!I10,'Perfil Vitaminico'!$B$3:$B$13,0)) -> 9 | M10: =K10=L10 -> TRUE | O10: Cabelo em mau estado | P10: 8
B11: Vitamina B1 (Tiamina) | C11: Ansiedade ou tensão | E11: =INDEX($P$3:$P$97,MATCH(F11,$O$3:$O$97,0)) -> 3 | F11: Ansiedade ou tensão | G11: Vitamina B1 (Tiamina) | I11: Vitamina E (Tocoferol) | J11: Vitamina E | K11: =INDEX('Tabela de Resultados'!$C$99:$AG$99,MATCH('Base de Dados'!J11,'Tabela de Resultados'!$C$2:$AG$2,0)) -> 8 | L11: =INDEX('Perfil Vitaminico'!$C$3:$C$13,MATCH('Base de Dados'!I11,'Perfil Vitaminico'!$B$3:$B$13,0)) -> 8 | M11: =K11=L11 -> TRUE | O11: Cabelo seco | P11: 9
B12: Vitamina B12 (Cobalamina) | C12: Ansiedade ou tensão | E12: =INDEX($P$3:$P$97,MATCH(F12,$O$3:$O$97,0)) -> 3 | F12: Ansiedade ou tensão | G12: Vitamina B12 (Cobalamina) | I12: Ácido Fólico (Vitamina B9) | J12: Ácido Fólico | K12: =INDEX('Tabela de Resultados'!$C$99:$AG$99,MATCH('Base de Dados'!J12,'Tabela de Resultados'!$C$2:$AG$2,0)) -> 9 | L12: =INDEX('Perfil Vitaminico'!$C$3:$C$13,MATCH('Base de Dados'!I12,'Perfil Vitaminico'!$B$3:$B$13,0)) -> 9 | M12: =K12=L12 -> TRUE | O12: Cabelo sem brilho ou oleoso | P12: 10
B13: Vitamina B3 (Niacina) | C13: Ansiedade ou tensão | E13: =INDEX($P$3:$P$97,MATCH(F13,$O$3:$O$97,0)) -> 3 | F13: Ansiedade ou tensão | G13: Vitamina B3 (Niacina) | I13: Biotina | J13: Biotina | K13: =INDEX('Tabela de Resultados'!$C$99:$AG$99,MATCH('Base de Dados'!J13,'Tabela de Resultados'!$C$2:$AG$2,0)) -> 9 | L13: =INDEX('Perfil Vitaminico'!$C$3:$C$13,MATCH('Base de Dados'!I13,'Perfil Vitaminico'!$B$3:$B$13,0)) -> 9 | M13: =K13=L13 -> TRUE | O13: Cãibras e tremores | P13: 11
B14: Vitamina D | C14: Ansiedade ou tensão | E14: =INDEX($P$3:$P$97,MATCH(F14,$O$3:$O$97,0)) -> 3 | F14: Ansiedade ou tensão | G14: Vitamina D | I14: Cálcio | J14: Cálcio | K14: =INDEX('Tabela de Resultados'!$C$99:$AG$99,MATCH('Base de Dados'!J14,'Tabela de Resultados'!$C$2:$AG$2,0)) -> 9 | L14: =INDEX('Perfil Mineral'!$C$3:$C$9,MATCH('Base de Dados'!I14,'Perfil Mineral'!$B$3:$B$9,0)) -> 9 | M14: =K14=L14 -> TRUE | O14: Cansaço após exercicio leve | P14: 12
B15: Vitamina B1 (Tiamina) | C15: Apatia | E15: =INDEX($P$3:$P$97,MATCH(F15,$O$3:$O$97,0)) -> 4 | F15: Apatia | G15: Vitamina B1 (Tiamina) | I15: Crómio | J15: Crómio | K15: =INDEX('Tabela de Resultados'!$C$99:$AG$99,MATCH('Base de Dados'!J15,'Tabela de Resultados'!$C$2:$AG$2,0)) -> 6 | L15: =INDEX('Perfil Mineral'!$C$3:$C$9,MATCH('Base de Dados'!I15,'Perfil Mineral'!$B$3:$B$9,0)) -> 6 | M15: =K15=L15 -> TRUE | O15: Cáries | P15: 13
B16: Vitamina B1 (Tiamina) | C16: Ardor nos pés ou tornozelos sensíveis | E16: =INDEX($P$3:$P$97,MATCH(F16,$O$3:$O$97,0)) -> 5 | F16: Ardor nos pés ou tornozelos sensíveis | G16: Vitamina B1 (Tiamina) | I16: Ferro | J16: Ferro | K16: =INDEX('Tabela de Resultados'!$C$99:$AG$99,MATCH('Base de Dados'!J16,'Tabela de Resultados'!$C$2:$AG$2,0)) -> 6 | L16: =INDEX('Perfil Mineral'!$C$3:$C$9,MATCH('Base de Dados'!I16,'Perfil Mineral'!$B$3:$B$9,0)) -> 6 | M16: =K16=L16 -> TRUE | O16: Caspa | P16: 14
B17: Magnésio | C17: Batimentos cardíacos irregulares ou rápidos | E17: =INDEX($P$3:$P$97,MATCH(F17,$O$3:$O$97,0)) -> 6 | F17: Batimentos cardíacos irregulares ou rápidos | G17: Magnésio | I17: Magnésio | J17: Magnésio | K17: =INDEX('Tabela de Resultados'!$C$99:$AG$99,MATCH('Base de Dados'!J17,'Tabela de Resultados'!$C$2:$AG$2,0)) -> 14 | L17: =INDEX('Perfil Mineral'!$C$3:$C$9,MATCH('Base de Dados'!I17,'Perfil Mineral'!$B$3:$B$9,0)) -> 14 | M17: =K17=L17 -> TRUE | O17: Cataratas | P17: 15
B18: Vitamina B1 (Tiamina) | C18: Batimentos cardíacos irregulares ou rápidos | E18: =INDEX($P$3:$P$97,MATCH(F18,$O$3:$O$97,0)) -> 6 | F18: Batimentos cardíacos irregulares ou rápidos | G18: Vitamina B1 (Tiamina) | I18: Manganésio | J18: Manganésio | K18: =INDEX('Tabela de Resultados'!$C$99:$AG$99,MATCH('Base de Dados'!J18,'Tabela de Resultados'!$C$2:$AG$2,0)) -> 5 | L18: =INDEX('Perfil Mineral'!$C$3:$C$9,MATCH('Base de Dados'!I18,'Perfil Mineral'!$B$3:$B$9,0)) -> 5 | M18: =K18=L18 -> TRUE | O18: Cicatrização lenta | P18: 16
B19: Vitamina B12 (Cobalamina) | C19: Boca hipersensível ao calor ou frio | E19: =INDEX($P$3:$P$97,MATCH(F19,$O$3:$O$97,0)) -> 7 | F19: Boca hipersensível ao calor ou frio | G19: Vitamina B12 (Cobalamina) | I19: Selénio | J19: Selénio | K19: =INDEX('Tabela de Resultados'!$C$99:$AG$99,MATCH('Base de Dados'!J19,'Tabela de Resultados'!$C$2:$AG$2,0)) -> 4 | L19: =INDEX('Perfil Mineral'!$C$3:$C$9,MATCH('Base de Dados'!I19,'Perfil Mineral'!$B$3:$B$9,0)) -> 4 | M19: =K19=L19 -> TRUE | O19: Constipações frequentes | P19: 17
B20: Biotina | C20: Cabelo em mau estado | E20: =INDEX($P$3:$P$97,MATCH(F20,$O$3:$O$97,0)) -> 8 | F20: Cabelo em mau estado | G20: Biotina | I20: Zinco | J20: Zinco | K20: =INDEX('Tabela de Resultados'!$C$99:$AG$99,MATCH('Base de Dados'!J20,'Tabela de Resultados'!$C$2:$AG$2,0)) -> 8 | L20: =INDEX('Perfil Mineral'!$C$3:$C$9,MATCH('Base de Dados'!I20,'Perfil Mineral'!$B$3:$B$9,0)) -> 8 | M20: =K20=L20 -> TRUE | O20: Contracções musculares | P20: 18
B21: Ómega 3 e Ómega 6 | C21: Cabelo seco | E21: =INDEX($P$3:$P$97,MATCH(F21,$O$3:$O$97,0)) -> 9 | F21: Cabelo seco | G21: Ómega 3 e Ómega 6 | I21: Ómega 3 e Ómega 6 | J21: Ómegas 3 e 6 | K21: =INDEX('Tabela de Resultados'!$C$99:$AG$99,MATCH('Base de Dados'!J21,'Tabela de Resultados'!$C$2:$AG$2,0)) -> 13 | L21: =INDEX('Perfil de A. Gordos'!C3,MATCH('Base de Dados'!I21,'Perfil de A. Gordos'!B3,0)) -> 13 | M21: =K21=L21 -> TRUE | O21: Crises ou convulsões | P21: 19
B22: Vitamina B2 (Riboflavina) | C22: Cabelo sem brilho ou oleoso | E22: =INDEX($P$3:$P$97,MATCH(F22,$O$3:$O$97,0)) -> 10 | F22: Cabelo sem brilho ou oleoso | G22: Vitamina B2 (Riboflavina) | I22: Alho | J22: Alho | K22: =INDEX('Tabela de Resultados'!$C$99:$AG$99,MATCH('Base de Dados'!J22,'Tabela de Resultados'!$C$2:$AG$2,0)) -> 9 | L22: =INDEX('Suplem. Adicionais'!$C$3:$C$14,MATCH('Base de Dados'!I22,'Suplem. Adicionais'!$B$3:$B$14,0)) -> 9 | M22: =K22=L22 -> TRUE | O22: Depressão | P22: 20
B23: Cálcio | C23: Cãibras e tremores | E23: =INDEX($P$3:$P$97,MATCH(F23,$O$3:$O$97,0)) -> 11 | F23: Cãibras e tremores | G23: Cálcio | I23: Black Cohosh | J23: Black Cohosh | K23: =INDEX('Tabela de Resultados'!$C$99:$AG$99,MATCH('Base de Dados'!J23,'Tabela de Resultados'!$C$2:$AG$2,0)) -> 1 | L23: =INDEX('Suplem. Adicionais'!$C$3:$C$14,MATCH('Base de Dados'!I23,'Suplem. Adicionais'!$B$3:$B$14,0)) -> 1 | M23: =K23=L23 -> TRUE | O23: Dermatite | P23: 21
B24: Magnésio | C24: Cãibras e tremores | E24: =INDEX($P$3:$P$97,MATCH(F24,$O$3:$O$97,0)) -> 11 | F24: Cãibras e tremores | G24: Magnésio | I24: Coenzima Q10 | J24: Coenzima Q10 | K24: =INDEX('Tabela de Resultados'!$C$99:$AG$99,MATCH('Base de Dados'!J24,'Tabela de Resultados'!$C$2:$AG$2,0)) -> 3 | L24: =INDEX('Suplem. Adicionais'!$C$3:$C$14,MATCH('Base de Dados'!I24,'Suplem. Adicionais'!$B$3:$B$14,0)) -> 3 | M24: =K24=L24 -> TRUE | O24: Diarreia | P24: 22
B25: Vitamina B1 (Tiamina) | C25: Cãibras e tremores | E25: =INDEX($P$3:$P$97,MATCH(F25,$O$3:$O$97,0)) -> 11 | F25: Cãibras e tremores | G25: Vitamina B1 (Tiamina) | I25: Concentrado de Frutas e Vegetais | J25: Concentrado de Frutas e Vegetais | K25: =INDEX('Tabela de Resultados'!$C$99:$AG$99,MATCH('Base de Dados'!J25,'Tabela de Resultados'!$C$2:$AG$2,0)) -> 4 | L25: =INDEX('Suplem. Adicionais'!$C$3:$C$14,MATCH('Base de Dados'!I25,'Suplem. Adicionais'!$B$3:$B$14,0)) -> 4 | M25: =K25=L25 -> TRUE | O25: Dificuldade em recordar os sonhos | P25: 23
B26: Vitamina B6 (Piridoxina) | C26: Cãibras e tremores | E26: =INDEX($P$3:$P$97,MATCH(F26,$O$3:$O$97,0)) -> 11 | F26: Cãibras e tremores | G26: Vitamina B6 (Piridoxina) | I26: Fibra em Pó | J26: Fibra em Pó | K26: =INDEX('Tabela de Resultados'!$C$99:$AG$99,MATCH('Base de Dados'!J26,'Tabela de Resultados'!$C$2:$AG$2,0)) -> 1 | L26: =INDEX('Suplem. Adicionais'!$C$3:$C$14,MATCH('Base de Dados'!I26,'Suplem. Adicionais'!$B$3:$B$14,0)) -> 1 | M26: =K26=L26 -> TRUE | O26: Dificuldades de concentração | P26: 24
B27: Coenzima Q10 | C27: Cansaço após exercicio leve | E27: =INDEX($P$3:$P$97,MATCH(F27,$O$3:$O$97,0)) -> 12 | F27: Cansaço após exercicio leve | G27: Coenzima Q10 | I27: Fibra Mastigável | J27: Fibra Mastigável | K27: =INDEX('Tabela de Resultados'!$C$99:$AG$99,MATCH('Base de Dados'!J27,'Tabela de Resultados'!$C$2:$AG$2,0)) -> 2 | L27: =INDEX('Suplem. Adicionais'!$C$3:$C$14,MATCH('Base de Dados'!I27,'Suplem. Adicionais'!$B$3:$B$14,0)) -> 2 | M27: =K27=L27 -> TRUE | O27: Diminuição do paladar ou do olfacto | P27: 25
B28: Ginseng Siberiano Plus | C28: Cansaço após exercicio leve | E28: =INDEX($P$3:$P$97,MATCH(F28,$O$3:$O$97,0)) -> 12 | F28: Cansaço após exercicio leve | G28: Ginseng Siberiano Plus | I28: Ginseng Siberiano Plus | J28: Ginseng Siberiano Plus | K28: =INDEX('Tabela de Resultados'!$C$99:$AG$99,MATCH('Base de Dados'!J28,'Tabela de Resultados'!$C$2:$AG$2,0)) -> 5 | L28: =INDEX('Suplem. Adicionais'!$C$3:$C$14,MATCH('Base de Dados'!I28,'Suplem. Adicionais'!$B$3:$B$14,0)) -> 5 | M28: =K28=L28 -> TRUE | O28: Dores de cabeça ou enxaquecas | P28: 26
B29: Proteína 100% Vegetal | C29: Cansaço após exercicio leve | E29: =INDEX($P$3:$P$97,MATCH(F29,$O$3:$O$97,0)) -> 12 | F29: Cansaço após exercicio leve | G29: Proteína 100% Vegetal | I29: Glucosamina com Boswellia | J29: Glucosamina com Boswellia | K29: =INDEX('Tabela de Resultados'!$C$99:$AG$99,MATCH('Base de Dados'!J29,'Tabela de Resultados'!$C$2:$AG$2,0)) -> 3 | L29: =INDEX('Suplem. Adicionais'!$C$3:$C$14,MATCH('Base de Dados'!I29,'Suplem. Adicionais'!$B$3:$B$14,0)) -> 3 | M29: =K29=L29 -> TRUE | O29: Dores de crescimento na infância | P29: 27
B30: Vitamina B1 (Tiamina) | C30: Cansaço após exercicio leve | E30: =INDEX($P$3:$P$97,MATCH(F30,$O$3:$O$97,0)) -> 12 | F30: Cansaço após exercicio leve | G30: Vitamina B1 (Tiamina) | I30: Mirtilo com Luteína | J30: Mirtilo com Luteína | K30: =INDEX('Tabela de Resultados'!$C$99:$AG$99,MATCH('Base de Dados'!J30,'Tabela de Resultados'!$C$2:$AG$2,0)) -> 3 | L30: =INDEX('Suplem. Adicionais'!$C$3:$C$14,MATCH('Base de Dados'!I30,'Suplem. Adicionais'!$B$3:$B$14,0)) -> 3 | M30: =K30=L30 -> TRUE | O30: Dores de estômago | P30: 28
B31: Vitamina E (Tocoferol) | C31: Cansaço após exercicio leve | E31: =INDEX($P$3:$P$97,MATCH(F31,$O$3:$O$97,0)) -> 12 | F31: Cansaço após exercicio leve | G31: Vitamina E (Tocoferol) | I31: Primrose Plus | J31: Primrose Plus | K31: =INDEX('Tabela de Resultados'!$C$99:$AG$99,MATCH('Base de Dados'!J31,'Tabela de Resultados'!$C$2:$AG$2,0)) -> 2 | L31: =INDEX('Suplem. Adicionais'!$C$3:$C$14,MATCH('Base de Dados'!I31,'Suplem. Adicionais'!$B$3:$B$14,0)) -> 2 | M31: =K31=L31 -> TRUE | O31: Dores lombares | P31: 29
B32: Cálcio | C32: Cáries | E32: =INDEX($P$3:$P$97,MATCH(F32,$O$3:$O$97,0)) -> 13 | F32: Cáries | G32: Cálcio | I32: Proteína 100% Vegetal | J32: Proteína 100% Vegetal | K32: =INDEX('Tabela de Resultados'!$C$99:$AG$99,MATCH('Base de Dados'!J32,'Tabela de Resultados'!$C$2:$AG$2,0)) -> 7 | L32: =INDEX('Suplem. Adicionais'!$C$3:$C$14,MATCH('Base de Dados'!I32,'Suplem. Adicionais'!$B$3:$B$14,0)) -> 7 | M32: =K32=L32 -> TRUE | O32: Dores nas articulações, problemas inflamatórios (ex: artrite) ou rigidez | P32: 30
B33: Vitamina A | C33: Caspa | E33: =INDEX($P$3:$P$97,MATCH(F33,$O$3:$O$97,0)) -> 14 | F33: Caspa | G33: Vitamina A | I33: Saw Palmetto e raiz de urtiga | J33: Saw Palmetto e raiz de urtiga | K33: =INDEX('Tabela de Resultados'!$C$99:$AG$99,MATCH('Base de Dados'!J33,'Tabela de Resultados'!$C$2:$AG$2,0)) -> 3 | L33: =INDEX('Suplem. Adicionais'!$C$3:$C$14,MATCH('Base de Dados'!I33,'Suplem. Adicionais'!$B$3:$B$14,0)) -> 3 | M33: =K33=L33 -> TRUE | O33: Dores nos olhos | P33: 31
B34: Selénio | C34: Cataratas | E34: =INDEX($P$3:$P$97,MATCH(F34,$O$3:$O$97,0)) -> 15 | F34: Cataratas | G34: Selénio | O34: Eczema | P34: 32
B35: Vitamina B2 (Riboflavina) | C35: Cataratas | E35: =INDEX($P$3:$P$97,MATCH(F35,$O$3:$O$97,0)) -> 15 | F35: Cataratas | G35: Vitamina B2 (Riboflavina) | O35: Embranquecimento prematuro dos cabelos | P35: 33
B36: Vitamina C (Ácido Ascórbico) | C36: Cicatrização lenta | E36: =INDEX($P$3:$P$97,MATCH(F36,$O$3:$O$97,0)) -> 16 | F36: Cicatrização lenta | G36: Vitamina C (Ácido Ascórbico) | O36: Equimoses fáceis (Nódoas Negras) | P36: 34
B37: Vitamina E (Tocoferol) | C37: Cicatrização lenta | E37: =INDEX($P$3:$P$97,MATCH(F37,$O$3:$O$97,0)) -> 16 | F37: Cicatrização lenta | G37: Vitamina E (Tocoferol) | O37: Espasmos musculares | P37: 35
B38: Zinco | C38: Cicatrização lenta | E38: =INDEX($P$3:$P$97,MATCH(F38,$O$3:$O$97,0)) -> 16 | F38: Cicatrização lenta | G38: Zinco | O38: Estrias | P38: 36
B39: Alho | C39: Constipações frequentes | E39: =INDEX($P$3:$P$97,MATCH(F39,$O$3:$O$97,0)) -> 17 | F39: Constipações frequentes | G39: Alho | O39: Fadiga ou moleza | P39: 37
B40: Concentrado de Frutas e Vegetais | C40: Constipações frequentes | E40: =INDEX($P$3:$P$97,MATCH(F40,$O$3:$O$97,0)) -> 17 | F40: Constipações frequentes | G40: Concentrado de Frutas e Vegetais | O40: Falta de apetência sexual | P40: 38
B41: Vitamina A | C41: Constipações frequentes | E41: =INDEX($P$3:$P$97,MATCH(F41,$O$3:$O$97,0)) -> 17 | F41: Constipações frequentes | G41: Vitamina A | O41: Falta de apetite | P41: 39
...

Sheet Perfil Vitaminico
B2: Vitamina | C2: Sintomas | E2: Vitamina A | F2: Pontuação | H2: Vitamina B1 (Tiamina) | I2: Pontuação | K2: Vitamina B2 (Riboflavina) | L2: Pontuação | N2: Vitamina B3 (Niacina) | O2: Pontuação | Q2: Vitamina B6 (Piridoxina) | R2: Pontuação | T2: Vitamina B12 (Cobalamina) | U2: Pontuação | W2: Vitamina C (Ácido Ascórbico) | X2: Pontuação | Z2: Ácido Fólico (Vitamina B9) | AA2: Pontuação | AC2: Biotina | AD2: Pontuação | AF2: Vitamina D | AG2: Pontuação | AI2: Vitamina E (Tocoferol) | AJ2: Pontuação
B3: Vitamina A | C3: =F12 -> 9 | E3: Ulcerações na boca e língua | F3: 2 | H3: Ardor nos pés ou tornozelos sensíveis | I3: 2 | K3: Olhos inchados, com ardor ou com sensação de grãos de areia | L3: 2 | N3: Falta de energia | O3: 1 | Q3: Falta de energia | R3: 2 | T3: Falta de energia | U3: 2 | W3: Constipações frequentes | X3: 2 | Z3: Falta de energia | AA3: 2 | AC3: Dermatite | AD3: 1 | AF3: Osteoporose | AG3: 2 | AI3: Cansaço após exercicio leve | AJ3: 2
B4: Vitamina B1 (Tiamina) | C4: =I21 -> 18 | E4: Constipações frequentes | F4: 2 | H4: Músculos sensíveis ou doridos | I4: 1 | K4: Sensibilidade a luzes intensas | L4: 2 | N4: Diarreia | O4: 1 | Q4: Dificuldade em recordar os sonhos | R4: 1 | T4: Eczema | U4: 1 | W4: Infecções frequentes | X4: 2 | Z4: Eczema | AA4: 1 | AC4: Pele seca e escamosa | AD4: 1 | AF4: Espasmos musculares | AG4: 2 | AI4: Equimoses fáceis (Nódoas Negras) | AJ4: 2
B5: Vitamina B2 (Riboflavina) | C5: =L12 -> 9 | E5: Infecções frequentes | F5: 2 | H5: Dores nos olhos | I5: 1 | K5: Ulcerações na boca e língua | L5: 1 | N5: Insónias ou nervosismo | O5: 1 | Q5: Retenção de líquidos | R5: 1 | T5: Dermatite | U5: 1 | W5: Falta de energia | X5: 1 | Z5: Lábios gretados | AA5: 1 | AC5: Cabelo em mau estado | AD5: 1 | AF5: Dores nas articulações, problemas inflamatórios (ex: artrite) ou rigidez | AG5: 2 | AI5: Falta de apetência sexual | AJ5: 1
B6: Vitamina B3 (Niacina) | C6: =O13 -> 10 | E6: Visão nocturna deficiente | F6: 1 | H6: Irritabilidade | I6: 1 | K6: Cataratas | L6: 1 | N6: Dores de cabeça ou enxaquecas | O6: 1 | Q6: Formigueiro nas mãos | R6: 1 | T6: Boca hipersensível ao calor ou frio | U6: 1 | W6: Gengivas em sangue ou sensíveis | X6: 1 | Z6: Embranquecimento prematuro dos cabelos | AA6: 1 | AC6: Embranquecimento prematuro dos cabelos | AD6: 1 | AF6: Ansiedade ou tensão | AG6: 1 | AI6: Cicatrização lenta | AJ6: 1
B7: Vitamina B6 (Piridoxina) | C7: =R11 -> 8 | E7: Acne | F7: 1 | H7: Dificuldades de concentração | I7: 1 | K7: Cabelo sem brilho ou oleoso | L7: 1 | N7: Falta de memória | O7: 1 | Q7: Depressão | R7: 1 | T7: Irritabilidade | U7: 1 | W7: Equimoses fáceis (Nódoas Negras) | X7: 1 | Z7: Ansiedade ou tensão | AA7: 1 | AC7: Músculos sensíveis ou doridos | AD7: 1 | AF7: Dores de cabeça ou enxaquecas | AG7: 1 | AI7: Varizes | AJ7: 1
B8: Vitamina B12 (Cobalamina) | C8: =U12 -> 9 | E8: Pele seca e escamosa | F8: 1 | H8: Formigueiro nas pernas | I8: 1 | K8: Eczema | L8: 1 | N8: Ansiedade ou tensão | O8: 1 | Q8: Nervosismo | R8: 1 | T8: Ansiedade ou tensão | U8: 1 | W8: Hemorragias nasais | X8: 1 | Z8: Falta de memória | AA8: 1 | AC8: Falta de apetite | AD8: 1 | AF8: Dores lombares | AG8: 1 | AI8: Pouca elasticidade da pele | AJ8: 1
B9: Vitamina C (Ácido Ascórbico) | C9: =X11 -> 8 | E9: Caspa | F9: 1 | H9: Falta de memória | I9: 1 | K9: Dermatite | L9: 1 | N9: Depressão | O9: 1 | Q9: Irritabilidade | R9: 1 | T9: Obstipação | U9: 1 | W9: Cicatrização lenta | X9: 1 | Z9: Depressão | AA9: 1 | AC9: Queda de cabelo | AD9: 1 | AF9: Perda de dentes | AG9: 1 | AI9: Perda de tónus muscular | AJ9: 1
B10: Ácido Fólico (Vitamina B9) | C10: =AA12 -> 9 | E10: Aftas ou cistite | F10: 1 | H10: Dores de estômago | I10: 1 | K10: Unhas quebradiças | L10: 1 | N10: Irritabilidade | O10: 1 | Q10: Cãibras e tremores | R10: 1 | T10: Músculos sensíveis ou doridos | U10: 1 | W10: Manchas vermelhas na pele | X10: 1 | Z10: Falta de apetite | AA10: 1 | AC10: Unhas quebradiças | AD10: 1 | AF10: Queda de cabelo | AG10: 1 | AI10: Infertilidade | AJ10: 1
B11: Biotina | C11: =AD12 -> 9 | E11: Diarreia | F11: 1 | H11: Obstipação | I11: 1 | K11: Lábios gretados | L11: 1 | N11: Gengivas em sangue ou sensíveis | O11: 1 | Q11: Total | R11: =COUNT(R3:R10) -> 8 | T11: Palidez | U11: 1 | W11: Total | X11: =COUNT(X3:X10) -> 8 | Z11: Dores de estômago | AA11: 1 | AC11: Náusea ou vómitos | AD11: 1 | AF11: Ossos fracos | AG11: 1 | AI11: Total | AJ11: =COUNT(AJ3:AJ10) -> 8
B12: Vitamina D | C12: =AG12 -> 9 | E12: Total | F12: =COUNT(F3:F11) -> 9 | H12: Formigueiro nas mãos | I12: 1 | K12: Total | L12: =COUNT(L3:L11) -> 9 | N12: Acne | O12: 1 | T12: Total | U12: =COUNT(U3:U11) -> 9 | Z12: Total | AA12: =COUNT(AA3:AA11) -> 9 | AC12: Total | AD12: =COUNT(AD3:AD11) -> 9 | AF12: Total | AG12: =COUNT(AG3:AG11) -> 9
B13: Vitamina E (Tocoferol) | C13: =AJ11 -> 8 | H13: Batimentos cardíacos irregulares ou rápidos | I13: 1 | N13: Total | O13: =COUNT(O3:O12) -> 10
B14: Total | C14: =SUM(C3:C13) -> 106 | H14: Cãibras e tremores | I14: 1
H15: Apatia | I15: 1
H16: Náusea ou vómitos | I16: 1
H17: Falta de energia | I17: 1
H18: Cansaço após exercicio leve | I18: 1
H19: Ansiedade ou tensão | I19: 1
H20: Ranger dos dentes | I20: 1
H21: Total | I21: =COUNT(I3:I20) -> 18

Sheet Perfil Mineral
B2: Minerais | C2: Sintomas | E2: Cálcio | F2: Pontuação | H2: Magnésio | I2: Pontuação | K2: Ferro | L2: Pontuação | N2: Manganésio | O2: Pontuação | Q2: Selénio | R2: Pontuação | T2: Zinco | U2: Pontuação | W2: Crómio | X2: Pontuação
B3: Cálcio | C3: =F12 -> 9 | E3: Cãibras e tremores | F3: 2 | H3: Cãibras e tremores | I3: 2 | K3: Palidez | L3: 2 | N3: Contracções musculares | O3: 2 | Q3: História familiar de cancro | R3: 2 | T3: Diminuição do paladar ou do olfacto | U3: 2 | W3: Suores excessivos ou frios | X3: 2
B4: Magnésio | C4: =I17 -> 14 | E4: Insónias ou nervosismo | F4: 2 | H4: Contracções musculares | I4: 2 | K4: Ulcerações na boca e língua | L4: 2 | N4: Dores de crescimento na infância | O4: 2 | Q4: Sinais de envelhecimento prematuro | R4: 2 | T4: Cicatrização lenta | U4: 2 | W4: Tonturas ou irritabilidade ao cabo de seis horas sem comida | X4: 2
B5: Ferro | C5: =L9 -> 6 | E5: Dores nas articulações, problemas inflamatórios (ex: artrite) ou rigidez | F5: 2 | H5: Ansiedade ou tensão | I5: 1 | K5: Fadiga ou moleza | L5: 2 | N5: Tonturas ou fraco sentido de equilíbrio | O5: 2 | Q5: Cataratas | R5: 2 | T5: Constipações frequentes | U5: 2 | W5: Necessidade de refeições frequentes | X5: 2
B6: Manganésio | C6: =O8 -> 5 | E6: Ansiedade ou tensão | F6: 2 | H6: Ossos fracos | I6: 1 | K6: Falta de apetite | L6: 2 | N6: Crises ou convulsões | O6: 2 | Q6: Tensão arterial elevada | R6: 2 | T6: Manchas brancas em mais do que 2 unhas | U6: 2 | W6: Mãos frias | X6: 2
B7: Selénio | C7: =R7 -> 4 | E7: Ossos fracos | F7: 2 | H7: Osteoporose | I7: 1 | K7: Náusea ou vómitos | L7: 2 | N7: Joelhos doridos | O7: 2 | Q7: Total | R7: =COUNT(R3:R6) -> 4 | T7: Infecções frequentes | U7: 2 | W7: Necessidade de dormir de mais ou sonolência durante o dia | X7: 2
B8: Zinco | C8: =U11 -> 8 | E8: Osteoporose | F8: 2 | H8: Fraqueza muscular | I8: 1 | K8: Períodos menstruais longos, perdas de sangue, escuro e / ou com coágulos | L8: 2 | N8: Total | O8: =COUNT(O3:O7) -> 5 | T8: Estrias | U8: 2 | W8: Embranquecimento prematuro dos cabelos | X8: 2
B9: Crómio | C9: =X9 -> 6 | E9: Dores de cabeça ou enxaquecas | F9: 2 | H9: Insónias | I9: 1 | K9: Total | L9: =COUNT(L3:L8) -> 6 | T9: Acne | U9: 2 | W9: Total | X9: =COUNT(X3:X8) -> 6
B10: Total | C10: =SUM(C3:C9) -> 52 | E10: Cáries | F10: 2 | H10: Tensão arterial elevada | I10: 1 | T10: Pele oleosa | U10: 2
E11: Tensão arterial elevada | F11: 2 | H11: Batimentos cardíacos irregulares ou rápidos | I11: 1 | T11: Total | U11: =COUNT(U3:U10) -> 8
E12: Total | F12: =COUNT(F3:F11) -> 9 | H12: Obstipação | I12: 1
H13: Dores de cabeça ou enxaquecas | I13: 1
H14: Crises ou convulsões | I14: 1
H15: Sensibilidade no peito | I15: 1
H16: Depressão | I16: 1
H17: Total | I17: =COUNT(I3:I16) -> 14

Sheet Perfil de A. Gordos
B2: Ácidos Gordos | C2: Sintomas | E2: Ómega 3 e Ómega 6 | F2: Pontuação
B3: Ómega 3 e Ómega 6 | C3: =F16 -> 13 | E3: Pele seca e escamosa | F3: 2
B4: Total | C4: =SUM(C3:C3) -> 13 | E4: Eczema | F4: 2
E5: Olhos secos | F5: 2
E6: Cabelo seco ou caspa | F6: 1
E7: Dores nas articulações, problemas inflamatórios (ex: artrite) ou rigidez | F7: 1
E8: Sede constante | F8: 1
E9: Sindrome pré menstrual e / ou com dores no peito | F9: 1
E10: Retenção de líquidos | F10: 1
E11: Infecções frequentes | F11: 1
E12: Memória fraca ou dificuldades de aprendizagem | F12: 1
E13: Tensão arterial elevada | F13: 1
E14: Nível elevado de lípidos no sangue (Colesterol) | F14: 1
E15: Dificuldades de concentração | F15: 1
E16: Total | F16: =COUNT(F3:F15) -> 13

Sheet Suplem. Adicionais
B2: Suplementos Adicionais | C2: Sintomas | E2: Glucosamina com Boswellia | F2: Pontuação | H2: Alho | I2: Pontuação | K2: Fibra em Pó | L2: Pontuação | N2: Fibra Mastigável | O2: Pontuação | Q2: Concentrado de Frutas e Vegetais | R2: Pontuação | T2: Mirtilo com Luteína | U2: Pontuação | W2: Saw Palmetto e raiz de urtiga | X2: Pontuação | Z2: Ginseng Siberiano Plus | AA2: Pontuação | AC2: Coenzima Q10 | AD2: Pontuação | AF2: Proteína 100% Vegetal | AG2: Pontuação | AI2: Primrose Plus | AJ2: Pontuação | AL2: Black Cohosh | AM2: Pontuação
B3: Glucosamina com Boswellia | C3: =F6 -> 3 | E3: Dores lombares | F3: 2 | H3: Acne | I3: 2 | K3: Obstipação | L3: 2 | N3: Dores de estômago | O3: 2 | Q3: Constipações frequentes | R3: 2 | T3: Dores nos olhos | U3: 2 | W3: Prevenção ou tratamento de problemas na próstata | X3: 2 | Z3: Cansaço após exercicio leve | AA3: 2 | AC3: Cansaço após exercicio leve | AD3: 2 | AF3: Cansaço após exercicio leve | AG3: 2 | AI3: Períodos menstruais longos, perdas de sangue, escuro e / ou com coágulos | AJ3: 2 | AL3: Menopausa (afrontamentos, suores espontâneos, mudanças de humor) | AM3: 2
B4: Alho | C4: =I12 -> 9 | E4: Dores nas articulações, problemas inflamatórios (ex: artrite) ou rigidez | F4: 2 | H4: Constipações frequentes | I4: 2 | K4: Total | L4: =COUNT(L3) -> 1 | N4: Obstipação | O4: 2 | Q4: Dores de estômago | R4: 2 | T4: Sensibilidade a luzes intensas | U4: 2 | W4: Melhorar função urinária anormal no homem | X4: 2 | Z4: Fadiga ou moleza | AA4: 2 | AC4: Fadiga ou moleza | AD4: 2 | AF4: Contracções musculares | AG4: 2 | AI4: Sindrome pré menstrual e / ou com dores no peito | AJ4: 2 | AL4: Total | AM4: =COUNT(AM3) -> 1
B5: Fibra em Pó | C5: =L4 -> 1 | E5: Joelhos doridos | F5: 2 | H5: Dores lombares | I5: 2 | N5: Total | O5: =COUNT(O3:O4) -> 2 | Q5: Infecções frequentes | R5: 2 | T5: Visão nocturna deficiente | U5: 2 | W5: Melhorar função reprodutora no homem | X5: 2 | Z5: Falta de energia | AA5: 2 | AC5: Falta de energia | AD5: 2 | AF5: Espasmos musculares | AG5: 2 | AI5: Total | AJ5: =COUNT(AJ3:AJ4) -> 2
B6: Fibra Mastigável | C6: =O5 -> 2 | E6: Total | F6: =COUNT(F3:F5) -> 3 | H6: Dores nas articulações, problemas inflamatórios (ex: artrite) ou rigidez | I6: 2 | Q6: Obstipação | R6: 2 | T6: Total | U6: =COUNT(U3:U5) -> 3 | W6: Total | X6: =COUNT(X3:X5) -> 3 | Z6: Falta de memória | AA6: 2 | AC6: Total | AD6: =COUNT(AD3:AD5) -> 3 | AF6: Fraqueza muscular | AG6: 2
B7: Concentrado de Frutas e Vegetais | C7: =R7 -> 4 | H7: Infecções frequentes | I7: 2 | Q7: Total | R7: =COUNT(R3:R6) -> 4 | Z7: Memória fraca ou dificuldades de aprendizagem | AA7: 2 | AF7: Músculos sensíveis ou doridos | AG7: 2
B8: Mirtilo com Luteína | C8: =U6 -> 3 | H8: Joelhos doridos | I8: 2 | Z8: Total | AA8: =COUNT(AA3:AA7) -> 5 | AF8: Obstipação | AG8: 2
B9: Saw Palmetto e raiz de urtiga | C9: =X6 -> 3 | H9: Nível elevado de lípidos no sangue (Colesterol) | I9: 2 | AF9: Perda de tónus muscular | AG9: 2
B10: Ginseng Siberiano Plus | C10: =AA8 -> 5 | H10: Retenção de líquidos | I10: 2 | AF10: Total | AG10: =COUNT(AG3:AG9) -> 7
B11: Coenzima Q10 | C11: =AD6 -> 3 | H11: Tensão arterial elevada | I11: 2
B12: Proteína 100% Vegetal | C12: =AG10 -> 7 | H12: Total | I12: =COUNT(I3:I11) -> 9
B13: Primrose Plus | C13: =AJ5 -> 2
B14: Black Cohosh | C14: =AM4 -> 1
B15: Total | C15: =SUM(C3:C14) -> 43
